<?xml version="1.0" encoding="utf-8"?>
<!-- This URDF was automatically created by SolidWorks to URDF Exporter! Originally created by Stephen Brawner (brawner@gmail.com) 
     Commit Version: 1.6.0-1-g15f4949  Build Version: 1.6.7594.29634
     For more information, please see http://wiki.ros.org/sw_urdf_exporter -->
<robot
  name="v1">
  <link
    name="Body">
    <inertial>
      <origin
        xyz="0.165830815971687 0.0380999957330949 6.72797849287521E-08"
        rpy="0 0 0" />
      <mass
        value="4.1454834394796" />
      <inertia
        ixx="0.0149485429992683"
        ixy="1.0440070936048E-09"
        ixz="5.3356648915208E-08"
        iyy="0.0416904644531089"
        iyz="2.30763106843912E-09"
        izz="0.0303553236657052" />
    </inertial>
    <visual>
      <origin
        xyz="0 0 0"
        rpy="0 0 0" />
      <geometry>
        <mesh
          filename="package://v1/meshes/Body.STL" />
      </geometry>
      <material
        name="">
        <color
          rgba="0.792156862745098 0.819607843137255 0.933333333333333 1" />
      </material>
    </visual>
    <collision>
      <origin
        xyz="0 0 0"
        rpy="0 0 0" />
      <geometry>
        <mesh
          filename="package://v1/meshes/Body.STL" />
      </geometry>
    </collision>
  </link>
  <link
    name="RUHumerus">
    <inertial>
      <origin
        xyz="0.022663870266748 0.0229280125509594 6.1824736996563E-09"
        rpy="0 0 0" />
      <mass
        value="0.0562874205713042" />
      <inertia
        ixx="2.50946970925149E-05"
        ixy="3.4486496266809E-11"
        ixz="-5.34572357071823E-13"
        iyy="1.43324424769428E-05"
        iyz="1.14161602737577E-11"
        izz="2.96716786302372E-05" />
    </inertial>
    <visual>
      <origin
        xyz="0 0 0"
        rpy="0 0 0" />
      <geometry>
        <mesh
          filename="package://v1/meshes/RUHumerus.STL" />
      </geometry>
      <material
        name="">
        <color
          rgba="0.792156862745098 0.819607843137255 0.933333333333333 1" />
      </material>
    </visual>
    <collision>
      <origin
        xyz="0 0 0"
        rpy="0 0 0" />
      <geometry>
        <mesh
          filename="package://v1/meshes/RUHumerus.STL" />
      </geometry>
    </collision>
  </link>
  <joint
    name="RShoulder1"
    type="continuous">
    <origin
      xyz="0.27432 -0.121591734569834 0.0381"
      rpy="-1.5707963267949 0 -1.5707963267949" />
    <parent
      link="Body" />
    <child
      link="RUHumerus" />
    <axis
      xyz="1 0 0" />
  </joint>
  <link
    name="RMHumerus">
    <inertial>
      <origin
        xyz="-3.47979352832706E-08 -0.0366746706630629 8.00093175046257E-09"
        rpy="0 0 0" />
      <mass
        value="0.138065758700322" />
      <inertia
        ixx="0.000119183734385309"
        ixy="4.21016703711818E-10"
        ixz="-4.18291851727919E-10"
        iyy="4.2657289532051E-05"
        iyz="5.06938412517806E-10"
        izz="0.000115572862627546" />
    </inertial>
    <visual>
      <origin
        xyz="0 0 0"
        rpy="0 0 0" />
      <geometry>
        <mesh
          filename="package://v1/meshes/RMHumerus.STL" />
      </geometry>
      <material
        name="">
        <color
          rgba="0.792156862745098 0.819607843137255 0.933333333333333 1" />
      </material>
    </visual>
    <collision>
      <origin
        xyz="0 0 0"
        rpy="0 0 0" />
      <geometry>
        <mesh
          filename="package://v1/meshes/RMHumerus.STL" />
      </geometry>
    </collision>
  </link>
  <joint
    name="RShoulder2"
    type="continuous">
    <origin
      xyz="0.0226638309978741 0.0435575675675675 0"
      rpy="0 0 3.14159265358979" />
    <parent
      link="RUHumerus" />
    <child
      link="RMHumerus" />
    <axis
      xyz="0 0 1" />
  </joint>
  <link
    name="RLHumerus">
    <inertial>
      <origin
        xyz="2.85344389228115E-08 0.0453008545995078 -4.65570376695368E-09"
        rpy="0 0 0" />
      <mass
        value="0.0924406074551833" />
      <inertia
        ixx="4.46849531177572E-05"
        ixy="-6.06465987997694E-11"
        ixz="9.51259691128854E-13"
        iyy="2.73751063103821E-05"
        iyz="1.71846938492772E-11"
        izz="4.75847417232106E-05" />
    </inertial>
    <visual>
      <origin
        xyz="0 0 0"
        rpy="0 0 0" />
      <geometry>
        <mesh
          filename="package://v1/meshes/RLHumerus.STL" />
      </geometry>
      <material
        name="">
        <color
          rgba="0.792156862745098 0.819607843137255 0.933333333333333 1" />
      </material>
    </visual>
    <collision>
      <origin
        xyz="0 0 0"
        rpy="0 0 0" />
      <geometry>
        <mesh
          filename="package://v1/meshes/RLHumerus.STL" />
      </geometry>
    </collision>
  </link>
  <joint
    name="RElbow1"
    type="continuous">
    <origin
      xyz="0 -0.0606510810810811 0"
      rpy="0 0 3.14159265358979" />
    <parent
      link="RMHumerus" />
    <child
      link="RLHumerus" />
    <axis
      xyz="0 1 0" />
  </joint>
  <link
    name="RRadius">
    <inertial>
      <origin
        xyz="2.77555756156289E-17 0.0770237882411253 0"
        rpy="0 0 0" />
      <mass
        value="0.225239465270569" />
      <inertia
        ixx="0.000378632787785578"
        ixy="-6.28657162893483E-20"
        ixz="-4.37907769765141E-10"
        iyy="5.98927289877368E-05"
        iyz="-2.10013437558746E-19"
        izz="0.000374806664124816" />
    </inertial>
    <visual>
      <origin
        xyz="0 0 0"
        rpy="0 0 0" />
      <geometry>
        <mesh
          filename="package://v1/meshes/RRadius.STL" />
      </geometry>
      <material
        name="">
        <color
          rgba="0.792156862745098 0.819607843137255 0.933333333333333 1" />
      </material>
    </visual>
    <collision>
      <origin
        xyz="0 0 0"
        rpy="0 0 0" />
      <geometry>
        <mesh
          filename="package://v1/meshes/RRadius.STL" />
      </geometry>
    </collision>
  </link>
  <joint
    name="RElbow2"
    type="continuous">
    <origin
      xyz="0 0.0770237837837839 0"
      rpy="0 0 0" />
    <parent
      link="RLHumerus" />
    <child
      link="RRadius" />
    <axis
      xyz="1 0 0" />
  </joint>
  <link
    name="RWrist">
    <inertial>
      <origin
        xyz="-5.54142620678988E-10 -0.0248602017447294 0.000380585345485046"
        rpy="0 0 0" />
      <mass
        value="0.0707291421737036" />
      <inertia
        ixx="3.33996262874122E-05"
        ixy="1.02617800920249E-11"
        ixz="5.97746340244636E-13"
        iyy="2.90416784477261E-05"
        iyz="9.11356668310129E-08"
        izz="1.36590319566293E-05" />
    </inertial>
    <visual>
      <origin
        xyz="0 0 0"
        rpy="0 0 0" />
      <geometry>
        <mesh
          filename="package://v1/meshes/RWrist.STL" />
      </geometry>
      <material
        name="">
        <color
          rgba="0.792156862745098 0.819607843137255 0.933333333333333 1" />
      </material>
    </visual>
    <collision>
      <origin
        xyz="0 0 0"
        rpy="0 0 0" />
      <geometry>
        <mesh
          filename="package://v1/meshes/RWrist.STL" />
      </geometry>
    </collision>
  </link>
  <joint
    name="RWrist1"
    type="continuous">
    <origin
      xyz="0 0.154047567567568 0"
      rpy="0 -1.5707963267949 0" />
    <parent
      link="RRadius" />
    <child
      link="RWrist" />
    <axis
      xyz="0 0 1" />
  </joint>
  <link
    name="RPalm">
    <inertial>
      <origin
        xyz="4.81852128197957E-08 -0.024433985583326 0.000379905031232308"
        rpy="0 0 0" />
      <mass
        value="0.0719515309236498" />
      <inertia
        ixx="3.41566805408971E-05"
        ixy="1.67722067856231E-11"
        ixz="9.50362515799047E-13"
        iyy="2.98417967548749E-05"
        iyz="9.07237613733749E-08"
        izz="1.39955427848438E-05" />
    </inertial>
    <visual>
      <origin
        xyz="0 0 0"
        rpy="0 0 0" />
      <geometry>
        <mesh
          filename="package://v1/meshes/RPalm.STL" />
      </geometry>
      <material
        name="">
        <color
          rgba="0.792156862745098 0.819607843137255 0.933333333333333 1" />
      </material>
    </visual>
    <collision>
      <origin
        xyz="0 0 0"
        rpy="0 0 0" />
      <geometry>
        <mesh
          filename="package://v1/meshes/RPalm.STL" />
      </geometry>
    </collision>
  </link>
  <joint
    name="RWrist2"
    type="continuous">
    <origin
      xyz="0 0 0"
      rpy="0 0 0" />
    <parent
      link="RWrist" />
    <child
      link="RPalm" />
    <axis
      xyz="0 1 0" />
  </joint>
  <link
    name="RRFingerU">
    <inertial>
      <origin
        xyz="-0.0126649206428162 -0.0013442938151873 0.0103020882956229"
        rpy="0 0 0" />
      <mass
        value="0.0104365547129789" />
      <inertia
        ixx="6.47820598125229E-07"
        ixy="8.86969972178146E-13"
        ixz="2.14754646038549E-09"
        iyy="2.69169048002805E-06"
        iyz="1.7674815544813E-13"
        izz="2.84642748020542E-06" />
    </inertial>
    <visual>
      <origin
        xyz="0 0 0"
        rpy="0 0 0" />
      <geometry>
        <mesh
          filename="package://v1/meshes/RRFingerU.STL" />
      </geometry>
      <material
        name="">
        <color
          rgba="0.792156862745098 0.819607843137255 0.933333333333333 1" />
      </material>
    </visual>
    <collision>
      <origin
        xyz="0 0 0"
        rpy="0 0 0" />
      <geometry>
        <mesh
          filename="package://v1/meshes/RRFingerU.STL" />
      </geometry>
    </collision>
  </link>
  <joint
    name="RRKnuckleU"
    type="continuous">
    <origin
      xyz="0 -0.05 0.000276794871794883"
      rpy="0 0 0" />
    <parent
      link="RPalm" />
    <child
      link="RRFingerU" />
    <axis
      xyz="0 0 1" />
  </joint>
  <link
    name="RRFingerL">
    <inertial>
      <origin
        xyz="-0.0128112396275469 -8.32667268468867E-17 0.00317500000000001"
        rpy="0 0 0" />
      <mass
        value="0.00367689699109764" />
      <inertia
        ixx="1.20384568003435E-07"
        ixy="-3.41026881090469E-22"
        ixz="1.49155300574575E-22"
        iyy="5.13888456072003E-07"
        iyz="-2.23758818044129E-22"
        izz="6.11743769207688E-07" />
    </inertial>
    <visual>
      <origin
        xyz="0 0 0"
        rpy="0 0 0" />
      <geometry>
        <mesh
          filename="package://v1/meshes/RRFingerL.STL" />
      </geometry>
      <material
        name="">
        <color
          rgba="0.792156862745098 0.819607843137255 0.933333333333333 1" />
      </material>
    </visual>
    <collision>
      <origin
        xyz="0 0 0"
        rpy="0 0 0" />
      <geometry>
        <mesh
          filename="package://v1/meshes/RRFingerL.STL" />
      </geometry>
    </collision>
  </link>
  <joint
    name="RRKnuckleL"
    type="continuous">
    <origin
      xyz="-0.0330199999999999 -0.00134428571428585 0.007072923076923"
      rpy="0 0 -1.5707963267949" />
    <parent
      link="RRFingerU" />
    <child
      link="RRFingerL" />
    <axis
      xyz="0 0 1" />
  </joint>
  <link
    name="RLFingerU">
    <inertial>
      <origin
        xyz="-0.0126649206428161 -0.00134429381518714 -0.0108645783710438"
        rpy="0 0 0" />
      <mass
        value="0.0104365547129788" />
      <inertia
        ixx="6.47820598125228E-07"
        ixy="8.86969970329839E-13"
        ixz="2.14754646038509E-09"
        iyy="2.69169048002804E-06"
        iyz="1.76748158358468E-13"
        izz="2.84642748020542E-06" />
    </inertial>
    <visual>
      <origin
        xyz="0 0 0"
        rpy="0 0 0" />
      <geometry>
        <mesh
          filename="package://v1/meshes/RLFingerU.STL" />
      </geometry>
      <material
        name="">
        <color
          rgba="0.792156862745098 0.819607843137255 0.933333333333333 1" />
      </material>
    </visual>
    <collision>
      <origin
        xyz="0 0 0"
        rpy="0 0 0" />
      <geometry>
        <mesh
          filename="package://v1/meshes/RLFingerU.STL" />
      </geometry>
    </collision>
  </link>
  <joint
    name="RLKnuckleU"
    type="continuous">
    <origin
      xyz="0 -0.05 0.000276794871794883"
      rpy="0 0 0" />
    <parent
      link="RPalm" />
    <child
      link="RLFingerU" />
    <axis
      xyz="0 0 1" />
  </joint>
  <link
    name="RLFingerL">
    <inertial>
      <origin
        xyz="-0.012811239627547 -8.32667268468867E-17 -0.00317499999999998"
        rpy="0 0 0" />
      <mass
        value="0.00367689699109764" />
      <inertia
        ixx="1.20384568003435E-07"
        ixy="-2.82957044074303E-22"
        ixz="4.51260046104007E-23"
        iyy="5.13888456072003E-07"
        iyz="-2.18912056642452E-22"
        izz="6.11743769207688E-07" />
    </inertial>
    <visual>
      <origin
        xyz="0 0 0"
        rpy="0 0 0" />
      <geometry>
        <mesh
          filename="package://v1/meshes/RLFingerL.STL" />
      </geometry>
      <material
        name="">
        <color
          rgba="0.792156862745098 0.819607843137255 0.933333333333333 1" />
      </material>
    </visual>
    <collision>
      <origin
        xyz="0 0 0"
        rpy="0 0 0" />
      <geometry>
        <mesh
          filename="package://v1/meshes/RLFingerL.STL" />
      </geometry>
    </collision>
  </link>
  <joint
    name="RLKnuckleL"
    type="continuous">
    <origin
      xyz="-0.0330199999999999 -0.0013442857142858 -0.00774374358974361"
      rpy="0 0 -1.5707963267949" />
    <parent
      link="RLFingerU" />
    <child
      link="RLFingerL" />
    <axis
      xyz="0 0 1" />
  </joint>
  <link
    name="LUHumerus">
    <inertial>
      <origin
        xyz="-0.0226637917290001 0.0229280125509593 6.52412784907241E-09"
        rpy="0 0 0" />
      <mass
        value="0.0562874205713043" />
      <inertia
        ixx="2.5094697092515E-05"
        ixy="3.44864962962202E-11"
        ixz="-5.34571844102473E-13"
        iyy="1.43324424769424E-05"
        iyz="1.11875878173675E-11"
        izz="2.96716786302376E-05" />
    </inertial>
    <visual>
      <origin
        xyz="0 0 0"
        rpy="0 0 0" />
      <geometry>
        <mesh
          filename="package://v1/meshes/LUHumerus.STL" />
      </geometry>
      <material
        name="">
        <color
          rgba="0.792156862745098 0.819607843137255 0.933333333333333 1" />
      </material>
    </visual>
    <collision>
      <origin
        xyz="0 0 0"
        rpy="0 0 0" />
      <geometry>
        <mesh
          filename="package://v1/meshes/LUHumerus.STL" />
      </geometry>
    </collision>
  </link>
  <joint
    name="LShoulder1"
    type="continuous">
    <origin
      xyz="0.27432 0.121591734569834 0.0381"
      rpy="-1.57079634169606 0 -1.5707963267949" />
    <parent
      link="Body" />
    <child
      link="LUHumerus" />
    <axis
      xyz="1 0 0" />
  </joint>
  <link
    name="LMHumerus">
    <inertial>
      <origin
        xyz="-3.47979352832706E-08 -0.036674670663063 8.00093141739566E-09"
        rpy="0 0 0" />
      <mass
        value="0.138065758700322" />
      <inertia
        ixx="0.000119183734385309"
        ixy="4.21016703607286E-10"
        ixz="-4.1829185172669E-10"
        iyy="4.2657289532051E-05"
        iyz="5.06938412454138E-10"
        izz="0.000115572862627546" />
    </inertial>
    <visual>
      <origin
        xyz="0 0 0"
        rpy="0 0 0" />
      <geometry>
        <mesh
          filename="package://v1/meshes/LMHumerus.STL" />
      </geometry>
      <material
        name="">
        <color
          rgba="0.792156862745098 0.819607843137255 0.933333333333333 1" />
      </material>
    </visual>
    <collision>
      <origin
        xyz="0 0 0"
        rpy="0 0 0" />
      <geometry>
        <mesh
          filename="package://v1/meshes/LMHumerus.STL" />
      </geometry>
    </collision>
  </link>
  <joint
    name="LShoulder2"
    type="continuous">
    <origin
      xyz="-0.0226638309978741 0.0435575675675675 0"
      rpy="0 0 3.14159265358979" />
    <parent
      link="LUHumerus" />
    <child
      link="LMHumerus" />
    <axis
      xyz="0 0 1" />
  </joint>
  <link
    name="LLHumerus">
    <inertial>
      <origin
        xyz="2.85344389505671E-08 0.0453008545995077 -4.65570382246483E-09"
        rpy="0 0 0" />
      <mass
        value="0.0924406074551832" />
      <inertia
        ixx="4.46849531177571E-05"
        ixy="-6.06465988261484E-11"
        ixz="9.5125969942878E-13"
        iyy="2.73751063103821E-05"
        iyz="1.71846938443234E-11"
        izz="4.75847417232105E-05" />
    </inertial>
    <visual>
      <origin
        xyz="0 0 0"
        rpy="0 0 0" />
      <geometry>
        <mesh
          filename="package://v1/meshes/LLHumerus.STL" />
      </geometry>
      <material
        name="">
        <color
          rgba="0.792156862745098 0.819607843137255 0.933333333333333 1" />
      </material>
    </visual>
    <collision>
      <origin
        xyz="0 0 0"
        rpy="0 0 0" />
      <geometry>
        <mesh
          filename="package://v1/meshes/LLHumerus.STL" />
      </geometry>
    </collision>
  </link>
  <joint
    name="LElbow1"
    type="continuous">
    <origin
      xyz="0 -0.0606510810810811 0"
      rpy="0 0 3.14159265358979" />
    <parent
      link="LMHumerus" />
    <child
      link="LLHumerus" />
    <axis
      xyz="0 1 0" />
  </joint>
  <link
    name="LRadius">
    <inertial>
      <origin
        xyz="5.55111512312578E-17 -0.0770237882411253 0"
        rpy="0 0 0" />
      <mass
        value="0.22523946527057" />
      <inertia
        ixx="0.000378632787785579"
        ixy="6.03841587597046E-20"
        ixz="4.37907769806552E-10"
        iyy="5.98927289877371E-05"
        iyz="1.95159067669717E-21"
        izz="0.000374806664124817" />
    </inertial>
    <visual>
      <origin
        xyz="0 0 0"
        rpy="0 0 0" />
      <geometry>
        <mesh
          filename="package://v1/meshes/LRadius.STL" />
      </geometry>
      <material
        name="">
        <color
          rgba="0.792156862745098 0.819607843137255 0.933333333333333 1" />
      </material>
    </visual>
    <collision>
      <origin
        xyz="0 0 0"
        rpy="0 0 0" />
      <geometry>
        <mesh
          filename="package://v1/meshes/LRadius.STL" />
      </geometry>
    </collision>
  </link>
  <joint
    name="LElbow2"
    type="continuous">
    <origin
      xyz="0 0.077023783783784 0"
      rpy="0 0 3.14159265358979" />
    <parent
      link="LLHumerus" />
    <child
      link="LRadius" />
    <axis
      xyz="1 0 0" />
  </joint>
  <link
    name="LWrist">
    <inertial>
      <origin
        xyz="-5.54142509656685E-10 -0.0248602017447294 0.000380585345484991"
        rpy="0 0 0" />
      <mass
        value="0.0707291421737037" />
      <inertia
        ixx="3.33996262874122E-05"
        ixy="1.02617800912574E-11"
        ixz="5.97746341673504E-13"
        iyy="2.90416784477261E-05"
        iyz="9.11356668310041E-08"
        izz="1.36590319566293E-05" />
    </inertial>
    <visual>
      <origin
        xyz="0 0 0"
        rpy="0 0 0" />
      <geometry>
        <mesh
          filename="package://v1/meshes/LWrist.STL" />
      </geometry>
      <material
        name="">
        <color
          rgba="0.792156862745098 0.819607843137255 0.933333333333333 1" />
      </material>
    </visual>
    <collision>
      <origin
        xyz="0 0 0"
        rpy="0 0 0" />
      <geometry>
        <mesh
          filename="package://v1/meshes/LWrist.STL" />
      </geometry>
    </collision>
  </link>
  <joint
    name="LWrist1"
    type="continuous">
    <origin
      xyz="0 -0.154047567567568 0"
      rpy="3.14159265358979 -1.5707963267949 0" />
    <parent
      link="LRadius" />
    <child
      link="LWrist" />
    <axis
      xyz="0 0 1" />
  </joint>
  <link
    name="LPalm">
    <inertial>
      <origin
        xyz="4.81852129863292E-08 -0.0244339855833261 0.000379905031232308"
        rpy="0 0 0" />
      <mass
        value="0.0719515309236498" />
      <inertia
        ixx="3.41566805408971E-05"
        ixy="1.67722067851626E-11"
        ixz="9.50362510965588E-13"
        iyy="2.98417967548748E-05"
        iyz="9.07237613733835E-08"
        izz="1.39955427848438E-05" />
    </inertial>
    <visual>
      <origin
        xyz="0 0 0"
        rpy="0 0 0" />
      <geometry>
        <mesh
          filename="package://v1/meshes/LPalm.STL" />
      </geometry>
      <material
        name="">
        <color
          rgba="0.792156862745098 0.819607843137255 0.933333333333333 1" />
      </material>
    </visual>
    <collision>
      <origin
        xyz="0 0 0"
        rpy="0 0 0" />
      <geometry>
        <mesh
          filename="package://v1/meshes/LPalm.STL" />
      </geometry>
    </collision>
  </link>
  <joint
    name="LWrist2"
    type="continuous">
    <origin
      xyz="0 0 0"
      rpy="0 0 0" />
    <parent
      link="LWrist" />
    <child
      link="LPalm" />
    <axis
      xyz="0 1 0" />
  </joint>
  <link
    name="LRFingerU">
    <inertial>
      <origin
        xyz="-0.0126649206428162 -0.00134429381518708 0.0103020882956229"
        rpy="0 0 0" />
      <mass
        value="0.0104365547129789" />
      <inertia
        ixx="6.47820598125229E-07"
        ixy="8.8696997016075E-13"
        ixz="2.14754646038562E-09"
        iyy="2.69169048002804E-06"
        iyz="1.767481611327E-13"
        izz="2.84642748020542E-06" />
    </inertial>
    <visual>
      <origin
        xyz="0 0 0"
        rpy="0 0 0" />
      <geometry>
        <mesh
          filename="package://v1/meshes/LRFingerU.STL" />
      </geometry>
      <material
        name="">
        <color
          rgba="0.792156862745098 0.819607843137255 0.933333333333333 1" />
      </material>
    </visual>
    <collision>
      <origin
        xyz="0 0 0"
        rpy="0 0 0" />
      <geometry>
        <mesh
          filename="package://v1/meshes/LRFingerU.STL" />
      </geometry>
    </collision>
  </link>
  <joint
    name="LRKnuckleU"
    type="continuous">
    <origin
      xyz="0 -0.05 0.000276794871794911"
      rpy="0 0 0" />
    <parent
      link="LPalm" />
    <child
      link="LRFingerU" />
    <axis
      xyz="0 0 1" />
  </joint>
  <link
    name="LRFingerL">
    <inertial>
      <origin
        xyz="-0.012811239627547 -1.11022302462516E-16 0.00317500000000001"
        rpy="0 0 0" />
      <mass
        value="0.00367689699109764" />
      <inertia
        ixx="1.20384568003435E-07"
        ixy="1.36169177153078E-22"
        ixz="3.30795030962378E-22"
        iyy="5.13888456072003E-07"
        iyz="1.59539229471891E-23"
        izz="6.11743769207688E-07" />
    </inertial>
    <visual>
      <origin
        xyz="0 0 0"
        rpy="0 0 0" />
      <geometry>
        <mesh
          filename="package://v1/meshes/LRFingerL.STL" />
      </geometry>
      <material
        name="">
        <color
          rgba="0.792156862745098 0.819607843137255 0.933333333333333 1" />
      </material>
    </visual>
    <collision>
      <origin
        xyz="0 0 0"
        rpy="0 0 0" />
      <geometry>
        <mesh
          filename="package://v1/meshes/LRFingerL.STL" />
      </geometry>
    </collision>
  </link>
  <joint
    name="LRKnuckleL"
    type="continuous">
    <origin
      xyz="-0.03302 -0.00134428571428574 0.00707292307692295"
      rpy="0 0 -1.5707963267949" />
    <parent
      link="LRFingerU" />
    <child
      link="LRFingerL" />
    <axis
      xyz="0 0 1" />
  </joint>
  <link
    name="LLFingerU">
    <inertial>
      <origin
        xyz="-0.0126649206428162 -8.10090144964803E-09 -0.0123144353600494"
        rpy="0 0 0" />
      <mass
        value="0.0104365547129789" />
      <inertia
        ixx="6.47820598125232E-07"
        ixy="8.86969969544327E-13"
        ixz="2.14754646038651E-09"
        iyy="2.69169048002805E-06"
        iyz="1.7674815805398E-13"
        izz="2.84642748020543E-06" />
    </inertial>
    <visual>
      <origin
        xyz="0 0 0"
        rpy="0 0 0" />
      <geometry>
        <mesh
          filename="package://v1/meshes/LLFingerU.STL" />
      </geometry>
      <material
        name="">
        <color
          rgba="0.792156862745098 0.819607843137255 0.933333333333333 1" />
      </material>
    </visual>
    <collision>
      <origin
        xyz="0 0 0"
        rpy="0 0 0" />
      <geometry>
        <mesh
          filename="package://v1/meshes/LLFingerU.STL" />
      </geometry>
    </collision>
  </link>
  <joint
    name="LLKnuckleU"
    type="continuous">
    <origin
      xyz="0 -0.0513442857142857 0.00172665186080059"
      rpy="0 0 0" />
    <parent
      link="LPalm" />
    <child
      link="LLFingerU" />
    <axis
      xyz="0 0 1" />
  </joint>
  <link
    name="LLFingerL">
    <inertial>
      <origin
        xyz="-0.0128112396275469 -2.77555756156289E-17 -0.00317499999999998"
        rpy="0 0 0" />
      <mass
        value="0.00367689699109764" />
      <inertia
        ixx="1.20384568003434E-07"
        ixy="2.58039647270358E-23"
        ixz="3.34505006134411E-22"
        iyy="5.13888456072002E-07"
        iyz="3.49370717704287E-23"
        izz="6.11743769207687E-07" />
    </inertial>
    <visual>
      <origin
        xyz="0 0 0"
        rpy="0 0 0" />
      <geometry>
        <mesh
          filename="package://v1/meshes/LLFingerL.STL" />
      </geometry>
      <material
        name="">
        <color
          rgba="0.792156862745098 0.819607843137255 0.933333333333333 1" />
      </material>
    </visual>
    <collision>
      <origin
        xyz="0 0 0"
        rpy="0 0 0" />
      <geometry>
        <mesh
          filename="package://v1/meshes/LLFingerL.STL" />
      </geometry>
    </collision>
  </link>
  <joint
    name="LLKnuckleL"
    type="continuous">
    <origin
      xyz="-0.03302 0 -0.00919360057874935"
      rpy="0 0 -1.5707963267949" />
    <parent
      link="LLFingerU" />
    <child
      link="LLFingerL" />
    <axis
      xyz="0 0 1" />
  </joint>
  <link
    name="RUFemur">
    <inertial>
      <origin
        xyz="0.022641000205622 -0.0236126458527025 -6.14393801459667E-09"
        rpy="0 0 0" />
      <mass
        value="0.058837160832887" />
      <inertia
        ixx="2.59185386877438E-05"
        ixy="-3.22027306679004E-11"
        ixz="-2.55770327002761E-13"
        iyy="1.48051965700891E-05"
        iyz="1.08782811970564E-11"
        izz="3.04715194779055E-05" />
    </inertial>
    <visual>
      <origin
        xyz="0 0 0"
        rpy="0 0 0" />
      <geometry>
        <mesh
          filename="package://v1/meshes/RUFemur.STL" />
      </geometry>
      <material
        name="">
        <color
          rgba="0.792156862745098 0.819607843137255 0.933333333333333 1" />
      </material>
    </visual>
    <collision>
      <origin
        xyz="0 0 0"
        rpy="0 0 0" />
      <geometry>
        <mesh
          filename="package://v1/meshes/RUFemur.STL" />
      </geometry>
    </collision>
  </link>
  <joint
    name="RHip1"
    type="continuous">
    <origin
      xyz="0.03048 -0.0787364118309958 0.0381"
      rpy="1.5707963267949 0 -1.57079634169606" />
    <parent
      link="Body" />
    <child
      link="RUFemur" />
    <axis
      xyz="1 0 0" />
  </joint>
  <link
    name="RMFemur">
    <inertial>
      <origin
        xyz="-4.34957657252655E-08 -0.031932877177532 1.060702716979E-08"
        rpy="0 0 0" />
      <mass
        value="0.123790820508356" />
      <inertia
        ixx="9.43360851552635E-05"
        ixy="4.47557249328389E-10"
        ixz="-4.30316018921808E-10"
        iyy="3.76217790275506E-05"
        iyz="4.80012269198868E-10"
        izz="9.05552888747606E-05" />
    </inertial>
    <visual>
      <origin
        xyz="0 0 0"
        rpy="0 0 0" />
      <geometry>
        <mesh
          filename="package://v1/meshes/RMFemur.STL" />
      </geometry>
      <material
        name="">
        <color
          rgba="0.792156862745098 0.819607843137255 0.933333333333333 1" />
      </material>
    </visual>
    <collision>
      <origin
        xyz="0 0 0"
        rpy="0 0 0" />
      <geometry>
        <mesh
          filename="package://v1/meshes/RMFemur.STL" />
      </geometry>
    </collision>
  </link>
  <joint
    name="RHip2"
    type="continuous">
    <origin
      xyz="0.0226409652141425 -0.0445895604395604 0"
      rpy="3.14159265358979 0 3.14159265358979" />
    <parent
      link="RUFemur" />
    <child
      link="RMFemur" />
    <axis
      xyz="0 0 1" />
  </joint>
  <link
    name="RLFemur">
    <inertial>
      <origin
        xyz="2.00190801852296E-08 -0.0260332209083051 3.19519880692676E-09"
        rpy="0 0 0" />
      <mass
        value="0.0813765868175624" />
      <inertia
        ixx="3.40076294026606E-05"
        ixy="3.59041395209103E-11"
        ixz="5.5323091695553E-13"
        iyy="2.49568185639496E-05"
        iyz="9.99145356402482E-12"
        izz="3.68818332146124E-05" />
    </inertial>
    <visual>
      <origin
        xyz="0 0 0"
        rpy="0 0 0" />
      <geometry>
        <mesh
          filename="package://v1/meshes/RLFemur.STL" />
      </geometry>
      <material
        name="">
        <color
          rgba="0.792156862745098 0.819607843137255 0.933333333333333 1" />
      </material>
    </visual>
    <collision>
      <origin
        xyz="0 0 0"
        rpy="0 0 0" />
      <geometry>
        <mesh
          filename="package://v1/meshes/RLFemur.STL" />
      </geometry>
    </collision>
  </link>
  <joint
    name="RKnee1"
    type="continuous">
    <origin
      xyz="0 -0.0684543956043956 0"
      rpy="0 0 0" />
    <parent
      link="RMFemur" />
    <child
      link="RLFemur" />
    <axis
      xyz="0 1 0" />
  </joint>
  <link
    name="RTibia">
    <inertial>
      <origin
        xyz="-2.77555756156289E-17 -0.0730923109520521 2.08166817117217E-17"
        rpy="0 0 0" />
      <mass
        value="0.197322267255763" />
      <inertia
        ixx="0.000264988132785359"
        ixy="-7.44462447756068E-21"
        ixz="3.73134589260056E-10"
        iyy="5.20314065854431E-05"
        iyz="8.89736109598491E-20"
        izz="0.000261642260704143" />
    </inertial>
    <visual>
      <origin
        xyz="0 0 0"
        rpy="0 0 0" />
      <geometry>
        <mesh
          filename="package://v1/meshes/RTibia.STL" />
      </geometry>
      <material
        name="">
        <color
          rgba="0.792156862745098 0.819607843137255 0.933333333333333 1" />
      </material>
    </visual>
    <collision>
      <origin
        xyz="0 0 0"
        rpy="0 0 0" />
      <geometry>
        <mesh
          filename="package://v1/meshes/RTibia.STL" />
      </geometry>
    </collision>
  </link>
  <joint
    name="RKnee2"
    type="continuous">
    <origin
      xyz="0 -0.05 0"
      rpy="0 0 0" />
    <parent
      link="RLFemur" />
    <child
      link="RTibia" />
    <axis
      xyz="1 0 0" />
  </joint>
  <link
    name="RFoot">
    <inertial>
      <origin
        xyz="0.00431987000828584 9.92670223798342E-10 3.92065171994638E-10"
        rpy="0 0 0" />
      <mass
        value="0.0576266868508424" />
      <inertia
        ixx="1.05875547592147E-05"
        ixy="3.92037871857128E-13"
        ixz="2.64833411768294E-12"
        iyy="6.33611195243211E-05"
        iyz="5.37963402669114E-13"
        izz="5.7440843831984E-05" />
    </inertial>
    <visual>
      <origin
        xyz="0 0 0"
        rpy="0 0 0" />
      <geometry>
        <mesh
          filename="package://v1/meshes/RFoot.STL" />
      </geometry>
      <material
        name="">
        <color
          rgba="0.792156862745098 0.819607843137255 0.933333333333333 1" />
      </material>
    </visual>
    <collision>
      <origin
        xyz="0 0 0"
        rpy="0 0 0" />
      <geometry>
        <mesh
          filename="package://v1/meshes/RFoot.STL" />
      </geometry>
    </collision>
  </link>
  <joint
    name="RAnkle"
    type="continuous">
    <origin
      xyz="0 -0.141756043956044 0"
      rpy="3.14159265358979 -1.5707963267949 0" />
    <parent
      link="RTibia" />
    <child
      link="RFoot" />
    <axis
      xyz="0 0 1" />
  </joint>
  <link
    name="RToe">
    <inertial>
      <origin
        xyz="0.0152672312202715 -9.9670521835904E-09 4.41560903674532E-08"
        rpy="0 0 0" />
      <mass
        value="0.0300993648154242" />
      <inertia
        ixx="8.31457715533237E-06"
        ixy="-3.97612203000878E-12"
        ixz="-8.97804618198221E-12"
        iyy="1.03832181900341E-05"
        iyz="8.67998305857423E-12"
        izz="4.34415013200784E-06" />
    </inertial>
    <visual>
      <origin
        xyz="0 0 0"
        rpy="0 0 0" />
      <geometry>
        <mesh
          filename="package://v1/meshes/RToe.STL" />
      </geometry>
      <material
        name="">
        <color
          rgba="0.792156862745098 0.819607843137255 0.933333333333333 1" />
      </material>
    </visual>
    <collision>
      <origin
        xyz="0 0 0"
        rpy="0 0 0" />
      <geometry>
        <mesh
          filename="package://v1/meshes/RToe.STL" />
      </geometry>
    </collision>
  </link>
  <joint
    name="RToe"
    type="continuous">
    <origin
      xyz="0.05000625 0 0"
      rpy="0 0 0" />
    <parent
      link="RFoot" />
    <child
      link="RToe" />
    <axis
      xyz="0 0 1" />
  </joint>
  <link
    name="LUFemur">
    <inertial>
      <origin
        xyz="-0.022640930222663 0.0236126458527025 5.80656082591058E-09"
        rpy="0 0 0" />
      <mass
        value="0.0588371608328871" />
      <inertia
        ixx="2.59185386877439E-05"
        ixy="3.22027308337893E-11"
        ixz="3.23615027751085E-13"
        iyy="1.48051965700891E-05"
        iyz="1.08782807088048E-11"
        izz="3.04715194779055E-05" />
    </inertial>
    <visual>
      <origin
        xyz="0 0 0"
        rpy="0 0 0" />
      <geometry>
        <mesh
          filename="package://v1/meshes/LUFemur.STL" />
      </geometry>
      <material
        name="">
        <color
          rgba="0.792156862745098 0.819607843137255 0.933333333333333 1" />
      </material>
    </visual>
    <collision>
      <origin
        xyz="0 0 0"
        rpy="0 0 0" />
      <geometry>
        <mesh
          filename="package://v1/meshes/LUFemur.STL" />
      </geometry>
    </collision>
  </link>
  <joint
    name="LHip1"
    type="continuous">
    <origin
      xyz="0.03048 0.0787364118309958 0.0381"
      rpy="-1.5707963267949 0 -1.5707963267949" />
    <parent
      link="Body" />
    <child
      link="LUFemur" />
    <axis
      xyz="1 0 0" />
  </joint>
  <link
    name="LMFemur">
    <inertial>
      <origin
        xyz="-4.34957657252655E-08 -0.031932877177532 1.06070271524428E-08"
        rpy="0 0 0" />
      <mass
        value="0.123790820508356" />
      <inertia
        ixx="9.43360851552635E-05"
        ixy="4.47557249344335E-10"
        ixz="-4.30316018919429E-10"
        iyy="3.76217790275506E-05"
        iyz="4.80012269184774E-10"
        izz="9.05552888747607E-05" />
    </inertial>
    <visual>
      <origin
        xyz="0 0 0"
        rpy="0 0 0" />
      <geometry>
        <mesh
          filename="package://v1/meshes/LMFemur.STL" />
      </geometry>
      <material
        name="">
        <color
          rgba="0.792156862745098 0.819607843137255 0.933333333333333 1" />
      </material>
    </visual>
    <collision>
      <origin
        xyz="0 0 0"
        rpy="0 0 0" />
      <geometry>
        <mesh
          filename="package://v1/meshes/LMFemur.STL" />
      </geometry>
    </collision>
  </link>
  <joint
    name="LHip2"
    type="continuous">
    <origin
      xyz="-0.0226409652141426 0.0445895604395605 0"
      rpy="0 0 3.14159265358979" />
    <parent
      link="LUFemur" />
    <child
      link="LMFemur" />
    <axis
      xyz="0 0 1" />
  </joint>
  <link
    name="LLFemur">
    <inertial>
      <origin
        xyz="2.00190801991074E-08 -0.0260332209083051 3.19519880692676E-09"
        rpy="0 0 0" />
      <mass
        value="0.0813765868175624" />
      <inertia
        ixx="3.40076294026605E-05"
        ixy="3.59041395159758E-11"
        ixz="5.532309170911E-13"
        iyy="2.49568185639496E-05"
        iyz="9.99145356393342E-12"
        izz="3.68818332146123E-05" />
    </inertial>
    <visual>
      <origin
        xyz="0 0 0"
        rpy="0 0 0" />
      <geometry>
        <mesh
          filename="package://v1/meshes/LLFemur.STL" />
      </geometry>
      <material
        name="">
        <color
          rgba="0.792156862745098 0.819607843137255 0.933333333333333 1" />
      </material>
    </visual>
    <collision>
      <origin
        xyz="0 0 0"
        rpy="0 0 0" />
      <geometry>
        <mesh
          filename="package://v1/meshes/LLFemur.STL" />
      </geometry>
    </collision>
  </link>
  <joint
    name="LKnee1"
    type="continuous">
    <origin
      xyz="0 -0.0684543956043956 0"
      rpy="0 0 0" />
    <parent
      link="LMFemur" />
    <child
      link="LLFemur" />
    <axis
      xyz="0 1 0" />
  </joint>
  <link
    name="LTibia">
    <inertial>
      <origin
        xyz="-1.67713967713645E-10 -0.0721566095737869 -0.0116580279261786"
        rpy="0 0 0" />
      <mass
        value="0.197322267255763" />
      <inertia
        ixx="0.000264988132785369"
        ixy="-5.9988773473273E-11"
        ixz="3.68233008569885E-10"
        iyy="5.73637801161854E-05"
        iyz="-3.3004380963554E-05"
        izz="0.000256309887173391" />
    </inertial>
    <visual>
      <origin
        xyz="0 0 0"
        rpy="0 0 0" />
      <geometry>
        <mesh
          filename="package://v1/meshes/LTibia.STL" />
      </geometry>
      <material
        name="">
        <color
          rgba="0.792156862745098 0.819607843137255 0.933333333333333 1" />
      </material>
    </visual>
    <collision>
      <origin
        xyz="0 0 0"
        rpy="0 0 0" />
      <geometry>
        <mesh
          filename="package://v1/meshes/LTibia.STL" />
      </geometry>
    </collision>
  </link>
  <joint
    name="LKnee2"
    type="continuous">
    <origin
      xyz="0 -0.05 0"
      rpy="-0.160181436409911 0 0" />
    <parent
      link="LLFemur" />
    <child
      link="LTibia" />
    <axis
      xyz="1 0 0" />
  </joint>
  <link
    name="LFoot">
    <inertial>
      <origin
        xyz="0.00431987000828584 9.92670168287191E-10 3.9206515811685E-10"
        rpy="0 0 0" />
      <mass
        value="0.0576266868508424" />
      <inertia
        ixx="1.05875547592147E-05"
        ixy="3.92037871432126E-13"
        ixz="2.6483341190867E-12"
        iyy="6.33611195243211E-05"
        iyz="5.37963403386106E-13"
        izz="5.7440843831984E-05" />
    </inertial>
    <visual>
      <origin
        xyz="0 0 0"
        rpy="0 0 0" />
      <geometry>
        <mesh
          filename="package://v1/meshes/LFoot.STL" />
      </geometry>
      <material
        name="">
        <color
          rgba="0.792156862745098 0.819607843137255 0.933333333333333 1" />
      </material>
    </visual>
    <collision>
      <origin
        xyz="0 0 0"
        rpy="0 0 0" />
      <geometry>
        <mesh
          filename="package://v1/meshes/LFoot.STL" />
      </geometry>
    </collision>
  </link>
  <joint
    name="LAnkle"
    type="continuous">
    <origin
      xyz="0 -0.139941334255675 -0.0226097095250998"
      rpy="1.57079623659819 -1.41061489038498 -1.57079623775286" />
    <parent
      link="LTibia" />
    <child
      link="LFoot" />
    <axis
      xyz="0 0 1" />
  </joint>
  <link
    name="LToe">
    <inertial>
      <origin
        xyz="0.0152672312202716 -9.96705223910155E-09 4.41560903535754E-08"
        rpy="0 0 0" />
      <mass
        value="0.0300993648154242" />
      <inertia
        ixx="8.31457715533236E-06"
        ixy="-3.97612203111906E-12"
        ixz="-8.97804618062952E-12"
        iyy="1.03832181900341E-05"
        iyz="8.67998305410331E-12"
        izz="4.34415013200783E-06" />
    </inertial>
    <visual>
      <origin
        xyz="0 0 0"
        rpy="0 0 0" />
      <geometry>
        <mesh
          filename="package://v1/meshes/LToe.STL" />
      </geometry>
      <material
        name="">
        <color
          rgba="0.792156862745098 0.819607843137255 0.933333333333333 1" />
      </material>
    </visual>
    <collision>
      <origin
        xyz="0 0 0"
        rpy="0 0 0" />
      <geometry>
        <mesh
          filename="package://v1/meshes/LToe.STL" />
      </geometry>
    </collision>
  </link>
  <joint
    name="LToe"
    type="continuous">
    <origin
      xyz="0.05000625 0 0"
      rpy="0 0 0" />
    <parent
      link="LFoot" />
    <child
      link="LToe" />
    <axis
      xyz="0 0 1" />
  </joint>
</robot>