<?xml version="1.0" encoding="utf-8"?>
<!-- This URDF was automatically created by SolidWorks to URDF Exporter! Originally created by Stephen Brawner (brawner@gmail.com) 
     Commit Version: 1.6.0-1-g15f4949  Build Version: 1.6.7594.29634
     For more information, please see http://wiki.ros.org/sw_urdf_exporter -->
<robot
  name="v1">
  <link
    name="Body">
    <inertial>
      <origin
        xyz="0.165830815971687 0.0380999957330949 6.72797849281136E-08"
        rpy="0 0 0" />
      <mass
        value="4.1454834394796" />
      <inertia
        ixx="0.0149485429992683"
        ixy="1.04400709349348E-09"
        ixz="5.33566489153261E-08"
        iyy="0.0416904644531089"
        iyz="2.30763106835205E-09"
        izz="0.0303553236657052" />
    </inertial>
    <visual>
      <origin
        xyz="0 0 0"
        rpy="0 0 0" />
      <geometry>
        <mesh
          filename="package://v1/meshes/Body.STL" />
      </geometry>
      <material
        name="">
        <color
          rgba="0.792156862745098 0.819607843137255 0.933333333333333 1" />
      </material>
    </visual>
    <collision>
      <origin
        xyz="0 0 0"
        rpy="0 0 0" />
      <geometry>
        <mesh
          filename="package://v1/meshes/Body.STL" />
      </geometry>
    </collision>
  </link>
  <link
    name="RUHumerus">
    <inertial>
      <origin
        xyz="0.022663870266748 0.0229280125509594 6.1824736996563E-09"
        rpy="0 0 0" />
      <mass
        value="0.0562874205713042" />
      <inertia
        ixx="2.50946970925149E-05"
        ixy="3.4486496266809E-11"
        ixz="-5.34572357123268E-13"
        iyy="1.43324424769428E-05"
        iyz="1.14161602736865E-11"
        izz="2.96716786302372E-05" />
    </inertial>
    <visual>
      <origin
        xyz="0 0 0"
        rpy="0 0 0" />
      <geometry>
        <mesh
          filename="package://v1/meshes/RUHumerus.STL" />
      </geometry>
      <material
        name="">
        <color
          rgba="0.792156862745098 0.819607843137255 0.933333333333333 1" />
      </material>
    </visual>
    <collision>
      <origin
        xyz="0 0 0"
        rpy="0 0 0" />
      <geometry>
        <mesh
          filename="package://v1/meshes/RUHumerus.STL" />
      </geometry>
    </collision>
  </link>
  <joint
    name="RShoulder1"
    type="continuous">
    <origin
      xyz="0.27432 -0.121591734569834 0.0381"
      rpy="-1.5707963267949 0 -1.5707963267949" />
    <parent
      link="Body" />
    <child
      link="RUHumerus" />
    <axis
      xyz="1 0 0" />
  </joint>
  <link
    name="RMHumerus">
    <inertial>
      <origin
        xyz="-3.47979352832706E-08 -0.0366746706630629 8.00093175046257E-09"
        rpy="0 0 0" />
      <mass
        value="0.138065758700322" />
      <inertia
        ixx="0.000119183734385309"
        ixy="4.21016703711105E-10"
        ixz="-4.18291851727919E-10"
        iyy="4.2657289532051E-05"
        iyz="5.06938412517806E-10"
        izz="0.000115572862627546" />
    </inertial>
    <visual>
      <origin
        xyz="0 0 0"
        rpy="0 0 0" />
      <geometry>
        <mesh
          filename="package://v1/meshes/RMHumerus.STL" />
      </geometry>
      <material
        name="">
        <color
          rgba="0.792156862745098 0.819607843137255 0.933333333333333 1" />
      </material>
    </visual>
    <collision>
      <origin
        xyz="0 0 0"
        rpy="0 0 0" />
      <geometry>
        <mesh
          filename="package://v1/meshes/RMHumerus.STL" />
      </geometry>
    </collision>
  </link>
  <joint
    name="RShoulder2"
    type="continuous">
    <origin
      xyz="0.0226638309978741 0.0435575675675675 0"
      rpy="0 0 3.14159265358979" />
    <parent
      link="RUHumerus" />
    <child
      link="RMHumerus" />
    <axis
      xyz="0 0 1" />
  </joint>
  <link
    name="RLHumerus">
    <inertial>
      <origin
        xyz="2.85344389228115E-08 0.0453008545995078 -4.65570371144253E-09"
        rpy="0 0 0" />
      <mass
        value="0.0924406074551832" />
      <inertia
        ixx="4.46849531177572E-05"
        ixy="-6.06465987997696E-11"
        ixz="9.51259690740704E-13"
        iyy="2.73751063103821E-05"
        iyz="1.71846938484002E-11"
        izz="4.75847417232106E-05" />
    </inertial>
    <visual>
      <origin
        xyz="0 0 0"
        rpy="0 0 0" />
      <geometry>
        <mesh
          filename="package://v1/meshes/RLHumerus.STL" />
      </geometry>
      <material
        name="">
        <color
          rgba="0.792156862745098 0.819607843137255 0.933333333333333 1" />
      </material>
    </visual>
    <collision>
      <origin
        xyz="0 0 0"
        rpy="0 0 0" />
      <geometry>
        <mesh
          filename="package://v1/meshes/RLHumerus.STL" />
      </geometry>
    </collision>
  </link>
  <joint
    name="RElbow1"
    type="continuous">
    <origin
      xyz="0 -0.0606510810810811 0"
      rpy="0 0 3.14159265358979" />
    <parent
      link="RMHumerus" />
    <child
      link="RLHumerus" />
    <axis
      xyz="0 1 0" />
  </joint>
  <link
    name="RRadius">
    <inertial>
      <origin
        xyz="2.77555756156289E-17 0.0770237882411253 -5.55111512312578E-17"
        rpy="0 0 0" />
      <mass
        value="0.225239465270569" />
      <inertia
        ixx="0.000378632787785578"
        ixy="-6.3305156107752E-20"
        ixz="-4.37907769765193E-10"
        iyy="5.98927289877368E-05"
        iyz="-2.09871265964704E-19"
        izz="0.000374806664124816" />
    </inertial>
    <visual>
      <origin
        xyz="0 0 0"
        rpy="0 0 0" />
      <geometry>
        <mesh
          filename="package://v1/meshes/RRadius.STL" />
      </geometry>
      <material
        name="">
        <color
          rgba="0.792156862745098 0.819607843137255 0.933333333333333 1" />
      </material>
    </visual>
    <collision>
      <origin
        xyz="0 0 0"
        rpy="0 0 0" />
      <geometry>
        <mesh
          filename="package://v1/meshes/RRadius.STL" />
      </geometry>
    </collision>
  </link>
  <joint
    name="RElbow2"
    type="continuous">
    <origin
      xyz="0 0.0770237837837839 0"
      rpy="0 0 0" />
    <parent
      link="RLHumerus" />
    <child
      link="RRadius" />
    <axis
      xyz="1 0 0" />
  </joint>
  <link
    name="RWrist">
    <inertial>
      <origin
        xyz="-1.80499076796181E-09 -0.00813891634217762 0.000367364016287702"
        rpy="0 0 0" />
      <mass
        value="0.0217142535290293" />
      <inertia
        ixx="7.75538309862475E-06"
        ixy="1.02617800954508E-11"
        ixz="5.97746342751812E-13"
        iyy="7.35311825881284E-06"
        iyz="-1.27624632546519E-08"
        izz="3.22756377894864E-06" />
    </inertial>
    <visual>
      <origin
        xyz="0 0 0"
        rpy="0 0 0" />
      <geometry>
        <mesh
          filename="package://v1/meshes/RWrist.STL" />
      </geometry>
      <material
        name="">
        <color
          rgba="0.792156862745098 0.819607843137255 0.933333333333333 1" />
      </material>
    </visual>
    <collision>
      <origin
        xyz="0 0 0"
        rpy="0 0 0" />
      <geometry>
        <mesh
          filename="package://v1/meshes/RWrist.STL" />
      </geometry>
    </collision>
  </link>
  <joint
    name="RWrist1"
    type="continuous">
    <origin
      xyz="0 0.154047567567568 0"
      rpy="0 -1.5707963267949 0" />
    <parent
      link="RRadius" />
    <child
      link="RWrist" />
    <axis
      xyz="0 0 1" />
  </joint>
  <link
    name="RPalm">
    <inertial>
      <origin
        xyz="0 -0.0177536698905907 0.00010964769997629"
        rpy="0 0 0" />
      <mass
        value="0.0490148886446744" />
      <inertia
        ixx="2.56442431887875E-05"
        ixy="-4.01486163322907E-21"
        ixz="-4.04520461113371E-21"
        iyy="2.16885601889133E-05"
        iyz="1.03898130085659E-07"
        izz="1.04314681776806E-05" />
    </inertial>
    <visual>
      <origin
        xyz="0 0 0"
        rpy="0 0 0" />
      <geometry>
        <mesh
          filename="package://v1/meshes/RPalm.STL" />
      </geometry>
      <material
        name="">
        <color
          rgba="0.792156862745098 0.819607843137255 0.933333333333333 1" />
      </material>
    </visual>
    <collision>
      <origin
        xyz="0 0 0"
        rpy="0 0 0" />
      <geometry>
        <mesh
          filename="package://v1/meshes/RPalm.STL" />
      </geometry>
    </collision>
  </link>
  <joint
    name="RWrist2"
    type="continuous">
    <origin
      xyz="0 -0.0145142857142857 0.000276794871794883"
      rpy="0 0 0" />
    <parent
      link="RWrist" />
    <child
      link="RPalm" />
    <axis
      xyz="0 1 0" />
  </joint>
  <link
    name="RRFinger1">
    <inertial>
      <origin
        xyz="-0.0126649206428162 -8.10090144964803E-09 0.00885223130661716"
        rpy="0 0 0" />
      <mass
        value="0.0104365547129789" />
      <inertia
        ixx="6.47820598125229E-07"
        ixy="8.86969972156842E-13"
        ixz="2.14754646038546E-09"
        iyy="2.69169048002805E-06"
        iyz="1.76748155452918E-13"
        izz="2.84642748020542E-06" />
    </inertial>
    <visual>
      <origin
        xyz="0 0 0"
        rpy="0 0 0" />
      <geometry>
        <mesh
          filename="package://v1/meshes/RRFinger1.STL" />
      </geometry>
      <material
        name="">
        <color
          rgba="0.792156862745098 0.819607843137255 0.933333333333333 1" />
      </material>
    </visual>
    <collision>
      <origin
        xyz="0 0 0"
        rpy="0 0 0" />
      <geometry>
        <mesh
          filename="package://v1/meshes/RRFinger1.STL" />
      </geometry>
    </collision>
  </link>
  <joint
    name="RRKnuckle1"
    type="continuous">
    <origin
      xyz="0 -0.0368300000000001 0.00144985698900574"
      rpy="0 0 0" />
    <parent
      link="RPalm" />
    <child
      link="RRFinger1" />
    <axis
      xyz="0 0 1" />
  </joint>
  <link
    name="RRFInger2">
    <inertial>
      <origin
        xyz="-0.0128112396275469 -1.11022302462516E-16 0.00317499999999998"
        rpy="0 0 0" />
      <mass
        value="0.00367689699109764" />
      <inertia
        ixx="1.20384568003435E-07"
        ixy="-3.45089830252734E-22"
        ixz="1.50632258559387E-22"
        iyy="5.13888456072003E-07"
        iyz="-2.23960766435866E-22"
        izz="6.11743769207688E-07" />
    </inertial>
    <visual>
      <origin
        xyz="0 0 0"
        rpy="0 0 0" />
      <geometry>
        <mesh
          filename="package://v1/meshes/RRFInger2.STL" />
      </geometry>
      <material
        name="">
        <color
          rgba="0.792156862745098 0.819607843137255 0.933333333333333 1" />
      </material>
    </visual>
    <collision>
      <origin
        xyz="0 0 0"
        rpy="0 0 0" />
      <geometry>
        <mesh
          filename="package://v1/meshes/RRFInger2.STL" />
      </geometry>
    </collision>
  </link>
  <joint
    name="RRKnuckle2"
    type="continuous">
    <origin
      xyz="-0.0330199999999999 0 0.00562306608791727"
      rpy="0 0 -1.5707963267949" />
    <parent
      link="RRFinger1" />
    <child
      link="RRFInger2" />
    <axis
      xyz="0 0 1" />
  </joint>
  <link
    name="RLFinger1">
    <inertial>
      <origin
        xyz="-0.0126649206428162 -8.10090133862573E-09 -0.0123144353600496"
        rpy="0 0 0" />
      <mass
        value="0.0104365547129788" />
      <inertia
        ixx="6.47820598125228E-07"
        ixy="8.86969970337357E-13"
        ixz="2.1475464603851E-09"
        iyy="2.69169048002804E-06"
        iyz="1.76748158357981E-13"
        izz="2.84642748020542E-06" />
    </inertial>
    <visual>
      <origin
        xyz="0 0 0"
        rpy="0 0 0" />
      <geometry>
        <mesh
          filename="package://v1/meshes/RLFinger1.STL" />
      </geometry>
      <material
        name="">
        <color
          rgba="0.792156862745098 0.819607843137255 0.933333333333333 1" />
      </material>
    </visual>
    <collision>
      <origin
        xyz="0 0 0"
        rpy="0 0 0" />
      <geometry>
        <mesh
          filename="package://v1/meshes/RLFinger1.STL" />
      </geometry>
    </collision>
  </link>
  <joint
    name="RLKnuckle1"
    type="continuous">
    <origin
      xyz="0 -0.0368300000000001 0.00144985698900574"
      rpy="0 0 0" />
    <parent
      link="RPalm" />
    <child
      link="RLFinger1" />
    <axis
      xyz="0 0 1" />
  </joint>
  <link
    name="RLFinger2">
    <inertial>
      <origin
        xyz="-0.012811239627547 -8.32667268468867E-17 -0.00317499999999998"
        rpy="0 0 0" />
      <mass
        value="0.00367689699109764" />
      <inertia
        ixx="1.20384568003435E-07"
        ixy="-2.85089309437617E-22"
        ixz="4.50793566593637E-23"
        iyy="5.13888456072003E-07"
        iyz="-2.21027086179487E-22"
        izz="6.11743769207688E-07" />
    </inertial>
    <visual>
      <origin
        xyz="0 0 0"
        rpy="0 0 0" />
      <geometry>
        <mesh
          filename="package://v1/meshes/RLFinger2.STL" />
      </geometry>
      <material
        name="">
        <color
          rgba="0.792156862745098 0.819607843137255 0.933333333333333 1" />
      </material>
    </visual>
    <collision>
      <origin
        xyz="0 0 0"
        rpy="0 0 0" />
      <geometry>
        <mesh
          filename="package://v1/meshes/RLFinger2.STL" />
      </geometry>
    </collision>
  </link>
  <joint
    name="RLKnuckle2"
    type="continuous">
    <origin
      xyz="-0.0330199999999999 0 -0.00919360057874935"
      rpy="0 0 -1.5707963267949" />
    <parent
      link="RLFinger1" />
    <child
      link="RLFinger2" />
    <axis
      xyz="0 0 1" />
  </joint>
  <link
    name="LUHumerus">
    <inertial>
      <origin
        xyz="-0.0226637917290001 0.0229280125509593 6.52412790458357E-09"
        rpy="0 0 0" />
      <mass
        value="0.0562874205713043" />
      <inertia
        ixx="2.5094697092515E-05"
        ixy="3.44864962966554E-11"
        ixz="-5.34571844060203E-13"
        iyy="1.43324424769424E-05"
        iyz="1.11875878172216E-11"
        izz="2.96716786302376E-05" />
    </inertial>
    <visual>
      <origin
        xyz="0 0 0"
        rpy="0 0 0" />
      <geometry>
        <mesh
          filename="package://v1/meshes/LUHumerus.STL" />
      </geometry>
      <material
        name="">
        <color
          rgba="0.792156862745098 0.819607843137255 0.933333333333333 1" />
      </material>
    </visual>
    <collision>
      <origin
        xyz="0 0 0"
        rpy="0 0 0" />
      <geometry>
        <mesh
          filename="package://v1/meshes/LUHumerus.STL" />
      </geometry>
    </collision>
  </link>
  <joint
    name="LShoulder1"
    type="continuous">
    <origin
      xyz="0.27432 0.121591734569834 0.0381"
      rpy="-1.57079634169606 0 -1.5707963267949" />
    <parent
      link="Body" />
    <child
      link="LUHumerus" />
    <axis
      xyz="1 0 0" />
  </joint>
  <link
    name="LMHumerus">
    <inertial>
      <origin
        xyz="-3.47979352832706E-08 -0.036674670663063 8.00093141739566E-09"
        rpy="0 0 0" />
      <mass
        value="0.138065758700322" />
      <inertia
        ixx="0.000119183734385309"
        ixy="4.21016703607286E-10"
        ixz="-4.1829185172669E-10"
        iyy="4.2657289532051E-05"
        iyz="5.06938412453936E-10"
        izz="0.000115572862627546" />
    </inertial>
    <visual>
      <origin
        xyz="0 0 0"
        rpy="0 0 0" />
      <geometry>
        <mesh
          filename="package://v1/meshes/LMHumerus.STL" />
      </geometry>
      <material
        name="">
        <color
          rgba="0.792156862745098 0.819607843137255 0.933333333333333 1" />
      </material>
    </visual>
    <collision>
      <origin
        xyz="0 0 0"
        rpy="0 0 0" />
      <geometry>
        <mesh
          filename="package://v1/meshes/LMHumerus.STL" />
      </geometry>
    </collision>
  </link>
  <joint
    name="LShoulder2"
    type="continuous">
    <origin
      xyz="-0.0226638309978741 0.0435575675675675 0"
      rpy="0 0 3.14159265358979" />
    <parent
      link="LUHumerus" />
    <child
      link="LMHumerus" />
    <axis
      xyz="0 0 1" />
  </joint>
  <link
    name="LLHumerus">
    <inertial>
      <origin
        xyz="2.85344389228115E-08 0.0453008545995077 -4.65570382246483E-09"
        rpy="0 0 0" />
      <mass
        value="0.0924406074551832" />
      <inertia
        ixx="4.46849531177571E-05"
        ixy="-6.06465988253211E-11"
        ixz="9.51259699423134E-13"
        iyy="2.73751063103821E-05"
        iyz="1.71846938432535E-11"
        izz="4.75847417232105E-05" />
    </inertial>
    <visual>
      <origin
        xyz="0 0 0"
        rpy="0 0 0" />
      <geometry>
        <mesh
          filename="package://v1/meshes/LLHumerus.STL" />
      </geometry>
      <material
        name="">
        <color
          rgba="0.792156862745098 0.819607843137255 0.933333333333333 1" />
      </material>
    </visual>
    <collision>
      <origin
        xyz="0 0 0"
        rpy="0 0 0" />
      <geometry>
        <mesh
          filename="package://v1/meshes/LLHumerus.STL" />
      </geometry>
    </collision>
  </link>
  <joint
    name="LElbow1"
    type="continuous">
    <origin
      xyz="0 -0.0606510810810811 0"
      rpy="0 0 3.14159265358979" />
    <parent
      link="LMHumerus" />
    <child
      link="LLHumerus" />
    <axis
      xyz="0 1 0" />
  </joint>
  <link
    name="LRadius">
    <inertial>
      <origin
        xyz="5.55111512312578E-17 -0.0770237882411253 0"
        rpy="0 0 0" />
      <mass
        value="0.22523946527057" />
      <inertia
        ixx="0.000378632787785579"
        ixy="6.45200622354167E-20"
        ixz="4.37907769806526E-10"
        iyy="5.98927289877371E-05"
        iyz="1.53800028193201E-21"
        izz="0.000374806664124817" />
    </inertial>
    <visual>
      <origin
        xyz="0 0 0"
        rpy="0 0 0" />
      <geometry>
        <mesh
          filename="package://v1/meshes/LRadius.STL" />
      </geometry>
      <material
        name="">
        <color
          rgba="0.792156862745098 0.819607843137255 0.933333333333333 1" />
      </material>
    </visual>
    <collision>
      <origin
        xyz="0 0 0"
        rpy="0 0 0" />
      <geometry>
        <mesh
          filename="package://v1/meshes/LRadius.STL" />
      </geometry>
    </collision>
  </link>
  <joint
    name="LElbow2"
    type="continuous">
    <origin
      xyz="0 0.077023783783784 0"
      rpy="0 0 3.14159265358979" />
    <parent
      link="LLHumerus" />
    <child
      link="LRadius" />
    <axis
      xyz="1 0 0" />
  </joint>
  <link
    name="LWrist">
    <inertial>
      <origin
        xyz="-1.80499076796181E-09 -0.00813891634217762 0.000367364016287702"
        rpy="0 0 0" />
      <mass
        value="0.0217142535290293" />
      <inertia
        ixx="7.75538309862477E-06"
        ixy="1.02617800950492E-11"
        ixz="5.97746345773122E-13"
        iyy="7.35311825881286E-06"
        iyz="-1.27624632546537E-08"
        izz="3.22756377894864E-06" />
    </inertial>
    <visual>
      <origin
        xyz="0 0 0"
        rpy="0 0 0" />
      <geometry>
        <mesh
          filename="package://v1/meshes/LWrist.STL" />
      </geometry>
      <material
        name="">
        <color
          rgba="0.792156862745098 0.819607843137255 0.933333333333333 1" />
      </material>
    </visual>
    <collision>
      <origin
        xyz="0 0 0"
        rpy="0 0 0" />
      <geometry>
        <mesh
          filename="package://v1/meshes/LWrist.STL" />
      </geometry>
    </collision>
  </link>
  <joint
    name="LWrist1"
    type="continuous">
    <origin
      xyz="0 -0.154047567567568 0"
      rpy="3.14159265358979 -1.5707963267949 0" />
    <parent
      link="LRadius" />
    <child
      link="LWrist" />
    <axis
      xyz="0 0 1" />
  </joint>
  <link
    name="LPalm">
    <inertial>
      <origin
        xyz="0 -0.0177536698905907 0.00010964769997629"
        rpy="0 0 0" />
      <mass
        value="0.0490148886446744" />
      <inertia
        ixx="2.56442431887875E-05"
        ixy="-4.17105761817786E-21"
        ixz="-3.9685464282277E-21"
        iyy="2.16885601889133E-05"
        iyz="1.03898130085659E-07"
        izz="1.04314681776806E-05" />
    </inertial>
    <visual>
      <origin
        xyz="0 0 0"
        rpy="0 0 0" />
      <geometry>
        <mesh
          filename="package://v1/meshes/LPalm.STL" />
      </geometry>
      <material
        name="">
        <color
          rgba="0.792156862745098 0.819607843137255 0.933333333333333 1" />
      </material>
    </visual>
    <collision>
      <origin
        xyz="0 0 0"
        rpy="0 0 0" />
      <geometry>
        <mesh
          filename="package://v1/meshes/LPalm.STL" />
      </geometry>
    </collision>
  </link>
  <joint
    name="LWrist2"
    type="continuous">
    <origin
      xyz="0 -0.0145142857142858 0.000276794871794911"
      rpy="0 0 0" />
    <parent
      link="LWrist" />
    <child
      link="LPalm" />
    <axis
      xyz="0 1 0" />
  </joint>
  <link
    name="LRFinger1">
    <inertial>
      <origin
        xyz="-0.0126649206428162 -8.10090133862573E-09 0.00885223130661722"
        rpy="0 0 0" />
      <mass
        value="0.0104365547129789" />
      <inertia
        ixx="6.47820598125229E-07"
        ixy="8.86969970151394E-13"
        ixz="2.14754646038558E-09"
        iyy="2.69169048002805E-06"
        iyz="1.76748161126199E-13"
        izz="2.84642748020542E-06" />
    </inertial>
    <visual>
      <origin
        xyz="0 0 0"
        rpy="0 0 0" />
      <geometry>
        <mesh
          filename="package://v1/meshes/LRFinger1.STL" />
      </geometry>
      <material
        name="">
        <color
          rgba="0.792156862745098 0.819607843137255 0.933333333333333 1" />
      </material>
    </visual>
    <collision>
      <origin
        xyz="0 0 0"
        rpy="0 0 0" />
      <geometry>
        <mesh
          filename="package://v1/meshes/LRFinger1.STL" />
      </geometry>
    </collision>
  </link>
  <joint
    name="LRKnuckle1"
    type="continuous">
    <origin
      xyz="0 -0.0368299999999999 0.00144985698900568"
      rpy="0 0 0" />
    <parent
      link="LPalm" />
    <child
      link="LRFinger1" />
    <axis
      xyz="0 0 1" />
  </joint>
  <link
    name="LRFinger2">
    <inertial>
      <origin
        xyz="-0.012811239627547 -1.11022302462516E-16 0.00317499999999998"
        rpy="0 0 0" />
      <mass
        value="0.00367689699109764" />
      <inertia
        ixx="1.20384568003435E-07"
        ixy="1.44620296430837E-22"
        ixz="3.30517772664218E-22"
        iyy="5.13888456072003E-07"
        iyz="1.61558713389257E-23"
        izz="6.11743769207688E-07" />
    </inertial>
    <visual>
      <origin
        xyz="0 0 0"
        rpy="0 0 0" />
      <geometry>
        <mesh
          filename="package://v1/meshes/LRFinger2.STL" />
      </geometry>
      <material
        name="">
        <color
          rgba="0.792156862745098 0.819607843137255 0.933333333333333 1" />
      </material>
    </visual>
    <collision>
      <origin
        xyz="0 0 0"
        rpy="0 0 0" />
      <geometry>
        <mesh
          filename="package://v1/meshes/LRFinger2.STL" />
      </geometry>
    </collision>
  </link>
  <joint
    name="LRKnuckle2"
    type="continuous">
    <origin
      xyz="-0.03302 0 0.00562306608791727"
      rpy="0 0 -1.5707963267949" />
    <parent
      link="LRFinger1" />
    <child
      link="LRFinger2" />
    <axis
      xyz="0 0 1" />
  </joint>
  <link
    name="LLFinger1">
    <inertial>
      <origin
        xyz="-0.0126649206428162 -8.10090144964803E-09 -0.0123144353600494"
        rpy="0 0 0" />
      <mass
        value="0.0104365547129789" />
      <inertia
        ixx="6.47820598125232E-07"
        ixy="8.86969969541433E-13"
        ixz="2.14754646038654E-09"
        iyy="2.69169048002805E-06"
        iyz="1.76748158053941E-13"
        izz="2.84642748020542E-06" />
    </inertial>
    <visual>
      <origin
        xyz="0 0 0"
        rpy="0 0 0" />
      <geometry>
        <mesh
          filename="package://v1/meshes/LLFinger1.STL" />
      </geometry>
      <material
        name="">
        <color
          rgba="0.792156862745098 0.819607843137255 0.933333333333333 1" />
      </material>
    </visual>
    <collision>
      <origin
        xyz="0 0 0"
        rpy="0 0 0" />
      <geometry>
        <mesh
          filename="package://v1/meshes/LLFinger1.STL" />
      </geometry>
    </collision>
  </link>
  <joint
    name="LLKnuckle1"
    type="continuous">
    <origin
      xyz="0 -0.0368299999999999 0.00144985698900568"
      rpy="0 0 0" />
    <parent
      link="LPalm" />
    <child
      link="LLFinger1" />
    <axis
      xyz="0 0 1" />
  </joint>
  <link
    name="LLFinger2">
    <inertial>
      <origin
        xyz="-0.0128112396275469 -2.77555756156289E-17 -0.00317500000000001"
        rpy="0 0 0" />
      <mass
        value="0.00367689699109764" />
      <inertia
        ixx="1.20384568003434E-07"
        ixy="2.44656358913032E-23"
        ixz="3.33118714643611E-22"
        iyy="5.13888456072002E-07"
        iyz="3.53409685539018E-23"
        izz="6.11743769207687E-07" />
    </inertial>
    <visual>
      <origin
        xyz="0 0 0"
        rpy="0 0 0" />
      <geometry>
        <mesh
          filename="package://v1/meshes/LLFinger2.STL" />
      </geometry>
      <material
        name="">
        <color
          rgba="0.792156862745098 0.819607843137255 0.933333333333333 1" />
      </material>
    </visual>
    <collision>
      <origin
        xyz="0 0 0"
        rpy="0 0 0" />
      <geometry>
        <mesh
          filename="package://v1/meshes/LLFinger2.STL" />
      </geometry>
    </collision>
  </link>
  <joint
    name="LLKnuckle2"
    type="continuous">
    <origin
      xyz="-0.03302 0 -0.00919360057874935"
      rpy="0 0 -1.5707963267949" />
    <parent
      link="LLFinger1" />
    <child
      link="LLFinger2" />
    <axis
      xyz="0 0 1" />
  </joint>
  <link
    name="RUFemur">
    <inertial>
      <origin
        xyz="0.022641000205622 -0.0236126458527025 -6.14393801459667E-09"
        rpy="0 0 0" />
      <mass
        value="0.058837160832887" />
      <inertia
        ixx="2.59185386877438E-05"
        ixy="-3.22027306679004E-11"
        ixz="-2.55770327008246E-13"
        iyy="1.48051965700891E-05"
        iyz="1.08782811971348E-11"
        izz="3.04715194779055E-05" />
    </inertial>
    <visual>
      <origin
        xyz="0 0 0"
        rpy="0 0 0" />
      <geometry>
        <mesh
          filename="package://v1/meshes/RUFemur.STL" />
      </geometry>
      <material
        name="">
        <color
          rgba="0.792156862745098 0.819607843137255 0.933333333333333 1" />
      </material>
    </visual>
    <collision>
      <origin
        xyz="0 0 0"
        rpy="0 0 0" />
      <geometry>
        <mesh
          filename="package://v1/meshes/RUFemur.STL" />
      </geometry>
    </collision>
  </link>
  <joint
    name="RHip1"
    type="continuous">
    <origin
      xyz="0.03048 -0.0787364118309958 0.0381"
      rpy="1.5707963267949 0 -1.57079634169606" />
    <parent
      link="Body" />
    <child
      link="RUFemur" />
    <axis
      xyz="1 0 0" />
  </joint>
  <link
    name="RMFemur">
    <inertial>
      <origin
        xyz="-4.34957657252655E-08 -0.031932877177532 1.060702716979E-08"
        rpy="0 0 0" />
      <mass
        value="0.123790820508356" />
      <inertia
        ixx="9.43360851552635E-05"
        ixy="4.4755724932845E-10"
        ixz="-4.30316018922221E-10"
        iyy="3.76217790275506E-05"
        iyz="4.80012269198859E-10"
        izz="9.05552888747606E-05" />
    </inertial>
    <visual>
      <origin
        xyz="0 0 0"
        rpy="0 0 0" />
      <geometry>
        <mesh
          filename="package://v1/meshes/RMFemur.STL" />
      </geometry>
      <material
        name="">
        <color
          rgba="0.792156862745098 0.819607843137255 0.933333333333333 1" />
      </material>
    </visual>
    <collision>
      <origin
        xyz="0 0 0"
        rpy="0 0 0" />
      <geometry>
        <mesh
          filename="package://v1/meshes/RMFemur.STL" />
      </geometry>
    </collision>
  </link>
  <joint
    name="RHip2"
    type="continuous">
    <origin
      xyz="0.0226409652141425 -0.0445895604395604 0"
      rpy="3.14159265358979 0 3.14159265358979" />
    <parent
      link="RUFemur" />
    <child
      link="RMFemur" />
    <axis
      xyz="0 0 1" />
  </joint>
  <link
    name="RLFemur">
    <inertial>
      <origin
        xyz="2.00190801852296E-08 -0.0260332209083051 3.19519880692676E-09"
        rpy="0 0 0" />
      <mass
        value="0.0813765868175624" />
      <inertia
        ixx="3.40076294026606E-05"
        ixy="3.5904139520962E-11"
        ixz="5.5323091654194E-13"
        iyy="2.49568185639496E-05"
        iyz="9.99145356174777E-12"
        izz="3.68818332146124E-05" />
    </inertial>
    <visual>
      <origin
        xyz="0 0 0"
        rpy="0 0 0" />
      <geometry>
        <mesh
          filename="package://v1/meshes/RLFemur.STL" />
      </geometry>
      <material
        name="">
        <color
          rgba="0.792156862745098 0.819607843137255 0.933333333333333 1" />
      </material>
    </visual>
    <collision>
      <origin
        xyz="0 0 0"
        rpy="0 0 0" />
      <geometry>
        <mesh
          filename="package://v1/meshes/RLFemur.STL" />
      </geometry>
    </collision>
  </link>
  <joint
    name="RKnee1"
    type="continuous">
    <origin
      xyz="0 -0.0684543956043956 0"
      rpy="0 0 0" />
    <parent
      link="RMFemur" />
    <child
      link="RLFemur" />
    <axis
      xyz="0 1 0" />
  </joint>
  <link
    name="RTibia">
    <inertial>
      <origin
        xyz="-2.77555756156289E-17 -0.0686637395234806 3.46944695195361E-17"
        rpy="0 0 0" />
      <mass
        value="0.197322267255763" />
      <inertia
        ixx="0.000264988132785359"
        ixy="-6.38479940401183E-21"
        ixz="3.73134589259823E-10"
        iyy="5.20314065854431E-05"
        iyz="8.87913273466858E-20"
        izz="0.000261642260704143" />
    </inertial>
    <visual>
      <origin
        xyz="0 0 0"
        rpy="0 0 0" />
      <geometry>
        <mesh
          filename="package://v1/meshes/RTibia.STL" />
      </geometry>
      <material
        name="">
        <color
          rgba="0.792156862745098 0.819607843137255 0.933333333333333 1" />
      </material>
    </visual>
    <collision>
      <origin
        xyz="0 0 0"
        rpy="0 0 0" />
      <geometry>
        <mesh
          filename="package://v1/meshes/RTibia.STL" />
      </geometry>
    </collision>
  </link>
  <joint
    name="RKnee2"
    type="continuous">
    <origin
      xyz="0 -0.0544285714285715 0"
      rpy="0 0 0" />
    <parent
      link="RLFemur" />
    <child
      link="RTibia" />
    <axis
      xyz="1 0 0" />
  </joint>
  <link
    name="RHeel">
    <inertial>
      <origin
        xyz="0.00431987000828584 9.92670168287191E-10 3.92065185872426E-10"
        rpy="0 0 0" />
      <mass
        value="0.0576266868508424" />
      <inertia
        ixx="1.05875547592147E-05"
        ixy="3.92037871760529E-13"
        ixz="2.64833411785163E-12"
        iyy="6.33611195243211E-05"
        iyz="5.37963402617415E-13"
        izz="5.7440843831984E-05" />
    </inertial>
    <visual>
      <origin
        xyz="0 0 0"
        rpy="0 0 0" />
      <geometry>
        <mesh
          filename="package://v1/meshes/RHeel.STL" />
      </geometry>
      <material
        name="">
        <color
          rgba="0.792156862745098 0.819607843137255 0.933333333333333 1" />
      </material>
    </visual>
    <collision>
      <origin
        xyz="0 0 0"
        rpy="0 0 0" />
      <geometry>
        <mesh
          filename="package://v1/meshes/RHeel.STL" />
      </geometry>
    </collision>
  </link>
  <joint
    name="RAnkle"
    type="continuous">
    <origin
      xyz="0 -0.137327472527473 0"
      rpy="3.14159265358979 -1.5707963267949 0" />
    <parent
      link="RTibia" />
    <child
      link="RHeel" />
    <axis
      xyz="0 0 1" />
  </joint>
  <link
    name="RToe">
    <inertial>
      <origin
        xyz="0.0152672312202715 -9.9670521835904E-09 4.41560903813309E-08"
        rpy="0 0 0" />
      <mass
        value="0.0300993648154242" />
      <inertia
        ixx="8.31457715533237E-06"
        ixy="-3.97612203000633E-12"
        ixz="-8.97804618171271E-12"
        iyy="1.03832181900341E-05"
        iyz="8.67998305855484E-12"
        izz="4.34415013200784E-06" />
    </inertial>
    <visual>
      <origin
        xyz="0 0 0"
        rpy="0 0 0" />
      <geometry>
        <mesh
          filename="package://v1/meshes/RToe.STL" />
      </geometry>
      <material
        name="">
        <color
          rgba="0.792156862745098 0.819607843137255 0.933333333333333 1" />
      </material>
    </visual>
    <collision>
      <origin
        xyz="0 0 0"
        rpy="0 0 0" />
      <geometry>
        <mesh
          filename="package://v1/meshes/RToe.STL" />
      </geometry>
    </collision>
  </link>
  <joint
    name="RToe"
    type="continuous">
    <origin
      xyz="0.05000625 0 0"
      rpy="0 0 0" />
    <parent
      link="RHeel" />
    <child
      link="RToe" />
    <axis
      xyz="0 0 1" />
  </joint>
  <link
    name="LUFemur">
    <inertial>
      <origin
        xyz="-0.022640930222663 0.0236126458527025 5.80656082591058E-09"
        rpy="0 0 0" />
      <mass
        value="0.0588371608328871" />
      <inertia
        ixx="2.59185386877438E-05"
        ixy="3.22027308335256E-11"
        ixz="3.23615027751084E-13"
        iyy="1.48051965700891E-05"
        iyz="1.08782807087764E-11"
        izz="3.04715194779055E-05" />
    </inertial>
    <visual>
      <origin
        xyz="0 0 0"
        rpy="0 0 0" />
      <geometry>
        <mesh
          filename="package://v1/meshes/LUFemur.STL" />
      </geometry>
      <material
        name="">
        <color
          rgba="0.792156862745098 0.819607843137255 0.933333333333333 1" />
      </material>
    </visual>
    <collision>
      <origin
        xyz="0 0 0"
        rpy="0 0 0" />
      <geometry>
        <mesh
          filename="package://v1/meshes/LUFemur.STL" />
      </geometry>
    </collision>
  </link>
  <joint
    name="LHip1"
    type="continuous">
    <origin
      xyz="0.03048 0.0787364118309958 0.0381"
      rpy="-1.5707963267949 0 -1.5707963267949" />
    <parent
      link="Body" />
    <child
      link="LUFemur" />
    <axis
      xyz="1 0 0" />
  </joint>
  <link
    name="LMFemur">
    <inertial>
      <origin
        xyz="-4.34957657252655E-08 -0.031932877177532 1.06070271524428E-08"
        rpy="0 0 0" />
      <mass
        value="0.123790820508356" />
      <inertia
        ixx="9.43360851552635E-05"
        ixy="4.47557249344378E-10"
        ixz="-4.30316018919016E-10"
        iyy="3.76217790275506E-05"
        iyz="4.80012269184774E-10"
        izz="9.05552888747607E-05" />
    </inertial>
    <visual>
      <origin
        xyz="0 0 0"
        rpy="0 0 0" />
      <geometry>
        <mesh
          filename="package://v1/meshes/LMFemur.STL" />
      </geometry>
      <material
        name="">
        <color
          rgba="0.792156862745098 0.819607843137255 0.933333333333333 1" />
      </material>
    </visual>
    <collision>
      <origin
        xyz="0 0 0"
        rpy="0 0 0" />
      <geometry>
        <mesh
          filename="package://v1/meshes/LMFemur.STL" />
      </geometry>
    </collision>
  </link>
  <joint
    name="LHip2"
    type="continuous">
    <origin
      xyz="-0.0226409652141426 0.0445895604395605 0"
      rpy="0 0 3.14159265358979" />
    <parent
      link="LUFemur" />
    <child
      link="LMFemur" />
    <axis
      xyz="0 0 1" />
  </joint>
  <link
    name="LLFemur">
    <inertial>
      <origin
        xyz="2.00190801991074E-08 -0.0260332209083051 3.19519880692676E-09"
        rpy="0 0 0" />
      <mass
        value="0.0813765868175624" />
      <inertia
        ixx="3.40076294026605E-05"
        ixy="3.59041395159758E-11"
        ixz="5.5323091750469E-13"
        iyy="2.49568185639496E-05"
        iyz="9.99145356632214E-12"
        izz="3.68818332146123E-05" />
    </inertial>
    <visual>
      <origin
        xyz="0 0 0"
        rpy="0 0 0" />
      <geometry>
        <mesh
          filename="package://v1/meshes/LLFemur.STL" />
      </geometry>
      <material
        name="">
        <color
          rgba="0.792156862745098 0.819607843137255 0.933333333333333 1" />
      </material>
    </visual>
    <collision>
      <origin
        xyz="0 0 0"
        rpy="0 0 0" />
      <geometry>
        <mesh
          filename="package://v1/meshes/LLFemur.STL" />
      </geometry>
    </collision>
  </link>
  <joint
    name="LKnee1"
    type="continuous">
    <origin
      xyz="0 -0.0684543956043956 0"
      rpy="0 0 0" />
    <parent
      link="LMFemur" />
    <child
      link="LLFemur" />
    <axis
      xyz="0 1 0" />
  </joint>
  <link
    name="LTibia">
    <inertial>
      <origin
        xyz="-1.57552387802795E-10 -0.0677847311179164 -0.0109516826387621"
        rpy="0 0 0" />
      <mass
        value="0.197322267255763" />
      <inertia
        ixx="0.000264988132785369"
        ixy="-5.9988773473273E-11"
        ixz="3.68233008569885E-10"
        iyy="5.73637801161854E-05"
        iyz="-3.3004380963554E-05"
        izz="0.000256309887173391" />
    </inertial>
    <visual>
      <origin
        xyz="0 0 0"
        rpy="0 0 0" />
      <geometry>
        <mesh
          filename="package://v1/meshes/LTibia.STL" />
      </geometry>
      <material
        name="">
        <color
          rgba="0.792156862745098 0.819607843137255 0.933333333333333 1" />
      </material>
    </visual>
    <collision>
      <origin
        xyz="0 0 0"
        rpy="0 0 0" />
      <geometry>
        <mesh
          filename="package://v1/meshes/LTibia.STL" />
      </geometry>
    </collision>
  </link>
  <joint
    name="LKnee2"
    type="continuous">
    <origin
      xyz="0 -0.0544285714285714 0"
      rpy="-0.160181436409911 0 0" />
    <parent
      link="LLFemur" />
    <child
      link="LTibia" />
    <axis
      xyz="1 0 0" />
  </joint>
  <link
    name="LHeel">
    <inertial>
      <origin
        xyz="0.00431987000828584 9.92670168287191E-10 3.9206515811685E-10"
        rpy="0 0 0" />
      <mass
        value="0.0576266868508424" />
      <inertia
        ixx="1.05875547592147E-05"
        ixy="3.92037871238927E-13"
        ixz="2.64833411878742E-12"
        iyy="6.33611195243211E-05"
        iyz="5.37963403386106E-13"
        izz="5.7440843831984E-05" />
    </inertial>
    <visual>
      <origin
        xyz="0 0 0"
        rpy="0 0 0" />
      <geometry>
        <mesh
          filename="package://v1/meshes/LHeel.STL" />
      </geometry>
      <material
        name="">
        <color
          rgba="0.792156862745098 0.819607843137255 0.933333333333333 1" />
      </material>
    </visual>
    <collision>
      <origin
        xyz="0 0 0"
        rpy="0 0 0" />
      <geometry>
        <mesh
          filename="package://v1/meshes/LHeel.STL" />
      </geometry>
    </collision>
  </link>
  <joint
    name="LAnkle"
    type="continuous">
    <origin
      xyz="0 -0.135569455799804 -0.0219033642376833"
      rpy="1.57079623659819 -1.41061489038498 -1.57079623775286" />
    <parent
      link="LTibia" />
    <child
      link="LHeel" />
    <axis
      xyz="0 0 1" />
  </joint>
  <link
    name="LToe">
    <inertial>
      <origin
        xyz="0.0152672312202715 -9.96705223910155E-09 4.41560903535754E-08"
        rpy="0 0 0" />
      <mass
        value="0.0300993648154242" />
      <inertia
        ixx="8.31457715533236E-06"
        ixy="-3.97612203112545E-12"
        ixz="-8.97804618066915E-12"
        iyy="1.03832181900341E-05"
        iyz="8.67998305410331E-12"
        izz="4.34415013200783E-06" />
    </inertial>
    <visual>
      <origin
        xyz="0 0 0"
        rpy="0 0 0" />
      <geometry>
        <mesh
          filename="package://v1/meshes/LToe.STL" />
      </geometry>
      <material
        name="">
        <color
          rgba="0.792156862745098 0.819607843137255 0.933333333333333 1" />
      </material>
    </visual>
    <collision>
      <origin
        xyz="0 0 0"
        rpy="0 0 0" />
      <geometry>
        <mesh
          filename="package://v1/meshes/LToe.STL" />
      </geometry>
    </collision>
  </link>
  <joint
    name="LToe"
    type="continuous">
    <origin
      xyz="0.05000625 0 0"
      rpy="0 0 0" />
    <parent
      link="LHeel" />
    <child
      link="LToe" />
    <axis
      xyz="0 0 1" />
  </joint>
</robot>